Workbook

Sheet Profile
A1: Category | B1: Question | C1: Inquiry Input | D1: Flags
A2: Borrower | B2: Borrower Type? | C2: Individual
A3: Borrower | B3: Borrower Help? | C3: Gift Funds Only
A4: Legal | B4: Citizenship Status? | C4: U.S. Citizen
A5: Legal | B5: Govt Issued ID Available? | C5: Yes
A6: Legal | B6: Marital Status? | C6: Married
A7: Legal | B7: Will your spouse be on the loan? | C7: Yes
A8: Legal | B8: Active Bankruptcy? | C8: No
A9: Legal | B9: Recently Discharged Bankruptcy? | C9: No
A10: Ownership | B10: Subject Property in Community Property State? | C10: Wisconsin
A11: Ownership | B11: Will Subject Property Be Owner Occupied? | C11: Owner Occupied
A12: Ownership | B12: Any party owning ≥ 25% Interest? | C12: No
A13: Housing | B13: Real Estate Owned? | C13: Rent
... A17: Credit | B17: Credit Profile? | C17: Good
B76: LISTS
B77: BorrowerType | C77: Help | D77: Citizenship | E77: Govt ID Available | F77: Marital Status | G77: Will your spouse mortgage? | H77: Active Bankruptcy | I77: Discharged Bankuptcy? | J77: Community Property State | K77: Owner Occupied | L77: Another party owns >25% Interest | M77: Current Housing | N77: Current Income | O77: Other Incomes | P77: Financials Available? | Q77: Credit | R77: Downpayment / Reserve Assets? | S77: Assets | T77: Other Assets & Credits | U77: Eligibility | V77: Column1
B78: Individual | C78: Co-Borrower (on Loan) | D78: U.S. Citizen | E78: Yes | F78: Single / Unmarried | G78: No | H78: No | I78: < 1 Year | J78: Wisconsin | K78: Owner Occupied | L78: Yes | M78: Rent | N78: Employed | O78: Alimony | P78: Yes | Q78: Exceptional | R78: Yes | S78: Bank Account | T78: Proceeds from Sale of Other Real Estate | U78: Ready to Proceed
B79: Joint | C79: Non-Occupant Co-Borrower | D79: Permanent Resident Alien | E79: No | F79: Married | G79: Yes | H79: Yes | I79: > 2 Years | J79: Arizona | K79: Non-Owner / Tenant Occupied | L79: No | M79: Own 1 Unit | N79: Self-Employed | O79: Automobile Allowance | P79: No | Q79: Very Good | R79: No | S79: Certificate of Deposit | T79: Proceeds from Sale of Non-Real Estate Asset | U79: Additional Review Needed
B80: Entity | C80: Gift Funds Only | D80: Non-Permanent Resident Alien | E80: Unsure | F80: Separated / Divorced | G80: Unsure | I80: 3+ Years | J80: Texas | M80: Own 1+ Units | N80: Multiple Sources | O80: Boarder Income | P80: Unsure | Q80: Good | R80: Unsure | S80: Stocks/ Options | T80: Gift | U80: Cannot Proceed at This Time
C81: Guarantor / Co-Signer | D81: Foreign National | E81: Expired / Renewal | I81: Filed / Terminated | J81: California | N81: Variable | O81: Capital Gains | Q81: Fair | S81: Mutual Fund | T81: Grant or Donation | U81: Explore Exceptional Circumstances
C82: None | I82: No | J82: Nevada | N82: Other (See List) | O82: Child Support | Q82: Poor | S82: Bonds | T82: Rent Credit
J83: New Mexico | O83: Disability | Q83: No Score / Locked | S83: Retirement (401k, IRA) | T83: Lot Equity
J84: Idaho | O84: Foster Care | S84: Bridge Loan Proceeds | T84: Employer Assistance
J85: Louisiana | O85: Housing or Parsonage | S85: Individual Development Account | T85: Sweat / Trade Equity
J86: Washington | O86: Interest and Dividends | S86: Trust Account | T86: Relocation Funds
J87: No | O87: Mortgage Credit Certificate | S87: Cash Value of Life Insurance
O88: Mortgage Differential Payments
O89: Notes Receiveable
O90: Public Assistance
O91: Retirement (Pension or IRA)
O92: Royalty Payments
O93: Separate Maintenance
O94: Social Security
O95: Trust
O96: Unemployment Benefits
O97: VA Compensation
O98: Other

Sheet Capacity
B1: Variable | C1: Inquiry Input
A2: Income | B2: Current Monthly | C2: 4000 | E2: * Stabilization of Income | G2: Borrower Structure Table
B3: 2-Year Average Annual | C3: 48000 | G3: Applicant Scenario | H3: Application | I3: Income Documentation | J3: Credit Report
G4: Individual | H4: Individual | I4: Individual | J4: Individual
A5: Debts | B5: Monthly Debt Payments | C5: 1000 | E5: * Guidelines Apply | G5: Co-Borrowers | H5: Apply Together | I5: All Eligible | J5: All Eligible
G6: Married (Both) | H6: Apply Together | I6: All Eligible | J6: All Eligible
A7: Calculation 1 | B7: Current Debt-to-Income Ratio (DTI) | C7: =SUM(C5/C2) -> 0.25 | E7: *Existing vs. Loan Impact | G7: Married (Non-Borrowing Spouse) | H7: Borrower | I7: Borrower Only | J7: Both (few exceptions)
B8: Qualifying Product Max DTI | C8: 0.4 | E8: *Vaires by Program | G8: Married (Non-Borrowing Spouse) in Marital State | H8: Borrower Applies; Spouse Acknowledge | I8: Borrower Only | J8: Both
G9: Borrower with Guarantor (Non-Occupying / Co- Sign) | H9: Apply Together | I9: Both (if allowed) | J9: Both
G10: Entity | H10: Entity | I10: Real Estate / Entity Financial Statements | J10: Varies; Guarantying Owners
A11: Calculation 2 | B11: Estimated Housing Payment (P&I ONLY) | C11: =SUM((C2*C8)-C5) -> 600 | E11: *Principal, Interest, Taxes, Ins., etc | G11: Entity with ≥25% Interested Party | H11: Entity Applies; Owners Acknowldege | I11: Tax Returns; Varies by Lender / Program | J11: Varies; Guarantying Owners
B13: Term Assumption | C13: 30
B14: Rate Assumption | C14: 0.065 | E14: * Risk Based Pricing
A15: Calculation 3 | B15: Max Loan Amount | C15: =PV(C14/12,C13*12,-C11) -> 94926.492
B17: Loan-to-Value Assumption | C17: 0.9
B18: Closing Cost Assumption | C18: 0.03
B19: Purchase Price | C19: =SUM(C15/C17) -> 105473.88
A20: Calculation 4 | B20: Cash Due From Borrower(s) (Assets / DPA / Gift / Reserves) | C20: =SUM(C19-C15)+(C19*C18) -> 13711.604
E27: Debt-To-Income | F27: Product Max DTI | G27: Loan-to-Value | H27: Term Scenario | I27: Rate Scenario
E28: Special / Exceptional 47% - 55% | F28: 0.55 | G28: 0.5 | H28: 15 | I28: 0.04
E29: Max Conventional >43% - 46% | F29: 0.5 | G29: 0.75 | H29: 25 | I29: 0.045
E30: Conventional 40% - 43% | F30: 0.45 | G30: 0.8 | H30: 30 | I30: 0.05
E31: Conventional 39% and Below | F31: 0.4 | G31: 0.9 | H31: 40 | I31: 0.055
G32: 0.91 | I32: 0.06
G33: 1 | I33: 0.065
G34: 1.1 | I34: 0.07
I35: 0.075
I36: 0.08
I37: 0.085
I38: 0.09
I39: 0.095
I40: 0.1
B59: Purchase Price | C59: 200000
B60: Current Value | C60: 210000
B61: Monthly Rent | C61: 4000
B62: Vacancy Rate % | C62: 0.1
B63: Other Income (annual) | C63: 0
B64: Gross Monthly Income | C64: 3600
B65: Taxes (annual) | C65: 3000
B66: Insurance (annual) | C66: 1200
...

Sheet Logic
B1: Plain Lanugage | C1: Formula | D1: Output Area
A2: Credit | B2: Exceptional | C2: Premium Pricing / Ease of Approval | D2: Profile
A3: Credit | B3: Very Good | C3: Creditworthy / Competitive Pricing | D3: Profile
A4: Credit | B4: Good | C4: Acceptable / Constraints May Apply | D4: Profile
A5: Credit | B5: Fair | C5: Additional Diligence / Fewer Options | D5: Profile
A6: Credit | B6: Poor | C6: Non-Conventional / Special Program Required | D6: Profile
A7: Credit | B7: No Score / Locked | C7: Manual Review of Exceptional Circumstances | D7: Profile
A8: Active Bankruptcy | C8: =IF(OR(Profile!C8="Yes",Profile!C9="<1 Year"),"Credit Event-financing only under legal exception","") | D8: Eligibility
A9: ID Available | C9: =IF(Profile!C5="No","Valid ID required to proceed","") | D9: Eligibility
A10: Citizenship | B10: Foreign National and Non Resident Alien | C10: =IF(OR(Profile!C4="Non-Permanent Resident Alien",Profile!C4="Foreign National"),"May require specialized loan program","") | D10: Eligibility
A11: Marital Property | C11: =IF(Profile!C10="Wisconsin","Spousal rights may impact title/loan structure","") -> Spousal rights may impact title/loan structure | D11: Eligibility
A12: Interested Party | B12: Entity Apply with Interested Party
A14: Joinder | B14: Texas & Married | C14: =IF(AND(Profile!C10="Texas",Profile!C6="Married"),"Acknowledgment of Debt by Non-Mortgaging Spouse","") | D14: Eligibility | E14: =IF(Profile!E10="Texas","Acknowledgment of Debt by Non-Mortgaging Spouse","") | F14: =IF(Profile!F10="Texas","Acknowledgment of Debt by Non-Mortgaging Spouse","") | G14: =IF(Profile!G10="Texas","Acknowledgment of Debt by Non-Mortgaging Spouse","") | H14: =IF(Profile!H10="Texas","Acknowledgment of Debt by Non-Mortgaging Spouse","") | I14: =IF(Profile!I10="Texas","Acknowledgment of Debt by Non-Mortgaging Spouse","") | J14: =IF(Profile!J10="Texas","Acknowledgment of Debt by Non-Mortgaging Spouse","") | K14: =IF(Profile!K10="Texas","Acknowledgment of Debt by Non-Mortgaging Spouse","")
A15: Joinder | B15: Wisconsin & Married | C15: =IF(AND(Profile!C10="Wisconsin",Profile!C6="Married"),"Acknowledgment of Debt by Non-Mortgaging Spouse","") -> Acknowledgment of Debt by Non-Mortgaging Spouse | D15: Eligibility
A16: Joinder | B16: Arizona & Married | C16: =IF(AND(Profile!C10="Arizona",Profile!C6="Married"),"Acknowledgment of Debt by Non-Mortgaging Spouse","") | D16: Eligibility
A17: Joinder | B17: California & Married | C17: =IF(AND(Profile!C10="California",Profile!C6="Married"),"Acknowledgment of Debt by Non-Mortgaging Spouse","") | D17: Eligibility
A18: Joinder | B18: Louisiana & Married | C18: =IF(AND(Profile!C10="Louisiana",Profile!C6="Married"),"Acknowledgment of Debt by Non-Mortgaging Spouse","") | D18: Eligibility
A19: Joinder | B19: Idaho & Married | C19: =IF(AND(Profile!C10="Idaho",Profile!C6="Married"),"Acknowledgment of Debt by Non-Mortgaging Spouse","") | D19: Eligibility
A20: Joinder | B20: Washington & Married | C20: =IF(AND(Profile!C10="Washington",Profile!C6="Married"),"Acknowledgment of Debt by Non-Mortgaging Spouse","") | D20: Eligibility
A21: Joinder | B21: New Mexico & Married | C21: =IF(AND(Profile!C10="New Mexico",Profile!C6="Married"),"Acknowledgment of Debt by Non-Mortgaging Spouse","") | D21: Eligibility
A22: Joinder | B22: Nevada & Married | C22: =IF(AND(Profile!C10="Nevada",Profile!C6="Married"),"Acknowledgment of Debt by Non-Mortgaging Spouse","") | D22: Eligibility
A23: > 25% Ownership | B23: if interested party ≥25% then docs required | C23: =IF(Profile!C12="Yes","Require Entity Organizing Documents","") | D23: Eligibility
A24: Paystub Flag | B24: No - missing paystubs | C24: =IF(Profile!P80="No","Missing Paystubs","Applicant Must Provide or Pay for Verification") -> Applicant Must Provide or Pay for Verification | D24: Docs
A25: Paystubs | B25: Yes - Available - We need them! | C25: =IF(Profile!C15="Yes","Most Recent 30 days ❌ Needed","") -> Most Recent 30 days ❌ Needed | D25: Docs
A26: Self-Employed | B26: No or Unsure if Financials Available | C26: =IF(OR(Profile!C15="No",(Profile!C15="Unsure")), "Tax Returns or Alt Document Program","") | D26: Docs
A27: Tax Returns | C27: =IF(Profile!C14="Multiple Sources","❌ Documentation Needed","") | D27: Docs
A28: Bank Statements | B28: Funds available | C28: =IF(Profile!C16="Yes","✅ Available","❌ Needed") -> ✅ Available | D28: Docs
A29: Asset Statements | B29: Yes assets - verify (see doc list) | C29: =IF(Profile!C16="Yes", "Verification of Asset","") -> Verification of Asset | D29: Docs
A30: Asset Statements | B30: No assets - need minimum investment / reserves | C30: =IF(Profile!C16="No", "Need Minimum Borrower Investment or Reserves","") | D30: Docs
A31: Asset Statements | B31: Unsure - Look at List or Discuss Options with LO | D31: Docs
A32: Borrower Structure | B32: Co-Borrower Income and CR required | C32: =IF(Profile!C3="Co-Borrower (on Loan)","Include income & debts for both applicants","") | D32: Docs
A33: Borrower Structure | B33: Non Occupant Co-Borrower (Guarantor Only) | C33: =IF(Profile!C3="Non-Occupant Co-Borrower","Apply Together, Programs Vary") -> FALSE
A34: Borrower Structure | B34: Non-Mortgaging Spouse | C34: =IF(AND(Profile!C6="Married",Profile!C7="No"), "Need Acknowledgment & Debts of Non-Mortgaging Spouse","") | D34: Docs
A35: Borrower Structure | B35: Gift Funds Only | C35: =IF(Profile!C3="Gift Funds Only","Helps Assets Only") -> Helps Assets Only | D35: Docs
A36: Borrower Structure | B36: Guarantor Only | C36: =IF(Profile!C3="Guarantor / Co-Signer","Apply Together / Programs Vary") -> FALSE
A37: REO Required | B37: Multiple properties owned - need REO Schedule | C37: =IF(Profile!C13="Own 1+ Units","Require REO Schedule","") | D37: Docs
B38: Entity Borrower with ≥25% Interested Party | C38: =IF(AND(Profile!C2="Entity",Profile!C12="Yes"),"Need Members ID; May Require Guaranty","")
B41: Flags
B42: ID Available | C42: No or Expired
B43: =Logic!A24 -> Paystub Flag
...

Sheet OUTPUT
A1: REAL ESTATE MORTGAGE READINESS SUMMARY
A2: Pre-Underwriting Snapshot (Not a Loan Approval*
B4: Prepared By | C4: Ngozie Omegbu, NMLS ID #2077106
B5: Market | C5: Wisconsin / Nationwide Referrals
B6: Date | C6: =NOW() -> 46132.87
B8: Borrower Profile Scenario
B9: Borrower Type | C9: =Profile!C2 -> Individual
B10: Borrower Help | C10: =Profile!C3 -> Gift Funds Only
B11: Real Estate Owned | C11: =Profile!C13 -> Rent
B12: Income Type | C12: =Profile!C14 -> Employed
B13: Desired Occupancy | C13: =Profile!C11 -> Owner Occupied
B14: Credit Profile | C14: =IF(AND(Profile!C17="Good"),"Acceptable / Constraints May Apply","") -> Acceptable / Constraints May Apply
B16: Eligibility Status
B17: ID Status | C17: =Profile!C4 -> U.S. Citizen
B18: Interested Party | C18: Yes, if Help, Married in Marital, or ≥25%.
B19: Exceptional Circumstance
B22: Income Status | C22: Additional Review Required
C23: Variable Type
C24: Co-Borrower Docs
C25: Unable to Locate Financial Statements
B27: Document Checklist
C28: REO Schedule
C29: 2 Years most recent Tax Returns
C30: Non-mortgaging spouse Acknowledgment & Debts
B33: Estimated Buying Power
B34: Estimated Income | C34: =Capacity!C2 -> 4000
B35: Monthly Debt(s) | C35: =Capacity!C5 -> 1000
B36: DTI Result: | C36: =Capacity!C8 -> 0.4
B37: Monthly Payment (P&I Only): | C37: =Capacity!C11 -> 600
B38: Estimated Loan Amount: | C38: =Capacity!C15 -> 94926.492
B39: Purchase Power: | C39: =Capacity!C19 -> 105473.88
B40: Cash-Required-To-Close: | C40: =Capacity!C20 -> 13711.604

Sheet Loan_Amortization
A1: Month | B1: Beginning Balance | C1: Payment | D1: Interest | E1: Principal | F1: Ending Balance
A2: 1 | B2: =[1]Inputs!B11 -> 240000 | C2: =PMT([1]Inputs!B12/12,[1]Inputs!B13*12,-[1]Inputs!B11) -> 1516.9633 | D2: =B2*[1]Inputs!B12/12 -> 1300 | E2: =C2-D2 -> 216.96326 | F2: =B2-E2 -> 239783.04
A3: =A2+1 -> 2 | B3: =F2 -> 239783.04 | C3: =C2 -> 1516.9633 | D3: =B3*[1]Inputs!B12/12 -> 1298.8248 | E3: =C3-D3 -> 218.13847 | F3: =B3-E3 -> 239564.9
A4: =A3+1 -> 3 | B4: =F3 -> 239564.9 | C4: =C2 -> 1516.9633 | D4: =B4*[1]Inputs!B12/12 -> 1297.6432 | E4: =C4-D4 -> 219.32006 | F4: =B4-E4 -> 239345.58
A5: =A4+1 -> 4 | B5: =F4 -> 239345.58 | C5: =C2 -> 1516.9633 | D5: =B5*[1]Inputs!B12/12 -> 1296.4552 | E5: =C5-D5 -> 220.50804 | F5: =B5-E5 -> 239125.07
A6: =A5+1 -> 5 | B6: =F5 -> 239125.07 | C6: =C2 -> 1516.9633 | D6: =B6*[1]Inputs!B12/12 -> 1295.2608 | E6: =C6-D6 -> 221.70246 | F6: =B6-E6 -> 238903.37
A7: =A6+1 -> 6 | B7: =F6 -> 238903.37 | C7: =C2 -> 1516.9633 | D7: =B7*[1]Inputs!B12/12 -> 1294.0599 | E7: =C7-D7 -> 222.90335 | F7: =B7-E7 -> 238680.46
A8: =A7+1 -> 7 | B8: =F7 -> 238680.46 | C8: =C2 -> 1516.9633 | D8: =B8*[1]Inputs!B12/12 -> 1292.8525 | E8: =C8-D8 -> 224.11074 | F8: =B8-E8 -> 238456.35
A9: =A8+1 -> 8 | B9: =F8 -> 238456.35 | C9: =C2 -> 1516.9633 | D9: =B9*[1]Inputs!B12/12 -> 1291.6386 | E9: =C9-D9 -> 225.32467 | F9: =B9-E9 -> 238231.03
A10: =A9+1 -> 9 | B10: =F9 -> 238231.03 | C10: =C2 -> 1516.9633 | D10: =B10*[1]Inputs!B12/12 -> 1290.4181 | E10: =C10-D10 -> 226.54518 | F10: =B10-E10 -> 238004.48
A11: =A10+1 -> 10 | B11: =F10 -> 238004.48 | C11: =C2 -> 1516.9633 | D11: =B11*[1]Inputs!B12/12 -> 1289.191 | E11: =C11-D11 -> 227.7723 | F11: =B11-E11 -> 237776.71
A12: =A11+1 -> 11 | B12: =F11 -> 237776.71 | C12: =C2 -> 1516.9633 | D12: =B12*[1]Inputs!B12/12 -> 1287.9572 | E12: =C12-D12 -> 229.00607 | F12: =B12-E12 -> 237547.71
A13: =A12+1 -> 12 | B13: =F12 -> 237547.71 | C13: =C2 -> 1516.9633 | D13: =B13*[1]Inputs!B12/12 -> 1286.7167 | E13: =C13-D13 -> 230.24652 | F13: =B13-E13 -> 237317.46
A14: =A13+1 -> 13 | B14: =F13 -> 237317.46 | C14: =C2 -> 1516.9633 | D14: =B14*[1]Inputs!B12/12 -> 1285.4696 | E14: =C14-D14 -> 231.49369 | F14: =B14-E14 -> 237085.97
A15: =A14+1 -> 14 | B15: =F14 -> 237085.97 | C15: =C2 -> 1516.9633 | D15: =B15*[1]Inputs!B12/12 -> 1284.2156 | E15: =C15-D15 -> 232.74761 | F15: =B15-E15 -> 236853.22
A16: =A15+1 -> 15 | B16: =F15 -> 236853.22 | C16: =C2 -> 1516.9633 | D16: =B16*[1]Inputs!B12/12 -> 1282.9549 | E16: =C16-D16 -> 234.00833 | F16: =B16-E16 -> 236619.21
A17: =A16+1 -> 16 | B17: =F16 -> 236619.21 | C17: =C2 -> 1516.9633 | D17: =B17*[1]Inputs!B12/12 -> 1281.6874 | E17: =C17-D17 -> 235.27587 | F17: =B17-E17 -> 236383.93
A18: =A17+1 -> 17 | B18: =F17 -> 236383.93 | C18: =C2 -> 1516.9633 | D18: =B18*[1]Inputs!B12/12 -> 1280.413 | E18: =C18-D18 -> 236.55028 | F18: =B18-E18 -> 236147.38
A19: =A18+1 -> 18 | B19: =F18 -> 236147.38 | C19: =C2 -> 1516.9633 | D19: =B19*[1]Inputs!B12/12 -> 1279.1317 | E19: =C19-D19 -> 237.8316 | F19: =B19-E19 -> 235909.55
A20: =A19+1 -> 19 | B20: =F19 -> 235909.55 | C20: =C2 -> 1516.9633 | D20: =B20*[1]Inputs!B12/12 -> 1277.8434 | E20: =C20-D20 -> 239.11985 | F20: =B20-E20 -> 235670.43
A21: =A20+1 -> 20 | B21: =F20 -> 235670.43 | C21: =C2 -> 1516.9633 | D21: =B21*[1]Inputs!B12/12 -> 1276.5482 | E21: =C21-D21 -> 240.41508 | F21: =B21-E21 -> 235430.02
A22: =A21+1 -> 21 | B22: =F21 -> 235430.02 | C22: =C2 -> 1516.9633 | D22: =B22*[1]Inputs!B12/12 -> 1275.2459 | E22: =C22-D22 -> 241.71733 | F22: =B22-E22 -> 235188.3
A23: =A22+1 -> 22 | B23: =F22 -> 235188.3 | C23: =C2 -> 1516.9633 | D23: =B23*[1]Inputs!B12/12 -> 1273.9366 | E23: =C23-D23 -> 243.02664 | F23: =B23-E23 -> 234945.27
A24: =A23+1 -> 23 | B24: =F23 -> 234945.27 | C24: =C2 -> 1516.9633 | D24: =B24*[1]Inputs!B12/12 -> 1272.6202 | E24: =C24-D24 -> 244.34303 | F24: =B24-E24 -> 234700.93
A25: =A24+1 -> 24 | B25: =F24 -> 234700.93 | C25: =C2 -> 1516.9633 | D25: =B25*[1]Inputs!B12/12 -> 1271.2967 | E25: =C25-D25 -> 245.66655 | F25: =B25-E25 -> 234455.26
A26: =A25+1 -> 25 | B26: =F25 -> 234455.26 | C26: =C2 -> 1516.9633 | D26: =B26*[1]Inputs!B12/12 -> 1269.966 | E26: =C26-D26 -> 246.99725 | F26: =B26-E26 -> 234208.27
A27: =A26+1 -> 26 | B27: =F26 -> 234208.27 | C27: =C2 -> 1516.9633 | D27: =B27*[1]Inputs!B12/12 -> 1268.6281 | E27: =C27-D27 -> 248.33515 | F27: =B27-E27 -> 233959.93
A28: =A27+1 -> 27 | B28: =F27 -> 233959.93 | C28: =C2 -> 1516.9633 | D28: =B28*[1]Inputs!B12/12 -> 1267.283 | E28: =C28-D28 -> 249.6803 | F28: =B28-E28 -> 233710.25
A29: =A28+1 -> 28 | B29: =F28 -> 233710.25 | C29: =C2 -> 1516.9633 | D29: =B29*[1]Inputs!B12/12 -> 1265.9305 | E29: =C29-D29 -> 251.03273 | F29: =B29-E29 -> 233459.22
A30: =A29+1 -> 29 | B30: =F29 -> 233459.22 | C30: =C2 -> 1516.9633 | D30: =B30*[1]Inputs!B12/12 -> 1264.5708 | E30: =C30-D30 -> 252.39249 | F30: =B30-E30 -> 233206.83
A31: =A30+1 -> 30 | B31: =F30 -> 233206.83 | C31: =C2 -> 1516.9633 | D31: =B31*[1]Inputs!B12/12 -> 1263.2036 | E31: =C31-D31 -> 253.75962 | F31: =B31-E31 -> 232953.07
A32: =A31+1 -> 31 | B32: =F31 -> 232953.07 | C32: =C2 -> 1516.9633 | D32: =B32*[1]Inputs!B12/12 -> 1261.8291 | E32: =C32-D32 -> 255.13415 | F32: =B32-E32 -> 232697.93
A33: =A32+1 -> 32 | B33: =F32 -> 232697.93 | C33: =C2 -> 1516.9633 | D33: =B33*[1]Inputs!B12/12 -> 1260.4471 | E33: =C33-D33 -> 256.51613 | F33: =B33-E33 -> 232441.42
A34: =A33+1 -> 33 | B34: =F33 -> 232441.42 | C34: =C2 -> 1516.9633 | D34: =B34*[1]Inputs!B12/12 -> 1259.0577 | E34: =C34-D34 -> 257.90559 | F34: =B34-E34 -> 232183.51
A35: =A34+1 -> 34 | B35: =F34 -> 232183.51 | C35: =C2 -> 1516.9633 | D35: =B35*[1]Inputs!B12/12 -> 1257.6607 | E35: =C35-D35 -> 259.30258 | F35: =B35-E35 -> 231924.21
A36: =A35+1 -> 35 | B36: =F35 -> 231924.21 | C36: =C2 -> 1516.9633 | D36: =B36*[1]Inputs!B12/12 -> 1256.2561 | E36: =C36-D36 -> 260.70714 | F36: =B36-E36 -> 231663.5
A37: =A36+1 -> 36 | B37: =F36 -> 231663.5 | C37: =C2 -> 1516.9633 | D37: =B37*[1]Inputs!B12/12 -> 1254.844 | E37: =C37-D37 -> 262.1193 | F37: =B37-E37 -> 231401.38
A38: =A37+1 -> 37 | B38: =F37 -> 231401.38 | C38: =C2 -> 1516.9633 | D38: =B38*[1]Inputs!B12/12 -> 1253.4241 | E38: =C38-D38 -> 263.53911 | F38: =B38-E38 -> 231137.84
A39: =A38+1 -> 38 | B39: =F38 -> 231137.84 | C39: =C2 -> 1516.9633 | D39: =B39*[1]Inputs!B12/12 -> 1251.9966 | E39: =C39-D39 -> 264.96662 | F39: =B39-E39 -> 230872.87
A40: =A39+1 -> 39 | B40: =F39 -> 230872.87 | C40: =C2 -> 1516.9633 | D40: =B40*[1]Inputs!B12/12 -> 1250.5614 | E40: =C40-D40 -> 266.40185 | F40: =B40-E40 -> 230606.47
...

Sheet Constant Chart
A1: Mortgage Constant Chart | D1: Formula: | E1: Constant = Monthly Payment * 12 / Loan
A2: Interest Rate | B2: 5 | C2: 6 | D2: 7 | E2: 8 | F2: 9 | G2: 10 | H2: 11 | I2: 12 | J2: 13 | K2: 14 | L2: 15 | M2: 16 | N2: 17 | O2: 18 | P2: 19 | Q2: 20 | R2: 21 | S2: 22 | T2: 23 | U2: 24 | V2: 25 | W2: 26 | X2: 27 | Y2: 28 | Z2: 29 | AA2: 30 | AB2: 31 | AC2: 32 | AD2: 33 | AE2: 34 | AF2: 35 | AG2: 36 | AH2: 37 | AI2: 38 | AJ2: 39 | AK2: 40
A3: 0.025 | B3: =PMT($A3/12,B$2*12,-1)*12 -> 0.21296834 | C3: =PMT($A3/12,C$2*12,-1)*12 -> 0.17965228 | D3: =PMT($A3/12,D$2*12,-1)*12 -> 0.15586992 | E3: =PMT($A3/12,E$2*12,-1)*12 -> 0.13804612 | F3: =PMT($A3/12,F$2*12,-1)*12 -> 0.12419468 | G3: =PMT($A3/12,G$2*12,-1)*12 -> 0.11312388 | H3: =PMT($A3/12,H$2*12,-1)*12 -> 0.10407536 | I3: =PMT($A3/12,I$2*12,-1)*12 -> 0.096543526 | ... AK3: =PMT($A3/12,AK$2*12,-1)*12 -> 0.039573387
A4: 0.0275 | B4: =PMT($A4/12,B$2*12,-1)*12 -> 0.21429372 | C4: =PMT($A4/12,C$2*12,-1)*12 -> 0.18098509 | D4: =PMT($A4/12,D$2*12,-1)*12 -> 0.15721114 | E4: =PMT($A4/12,E$2*12,-1)*12 -> 0.13939636 | F4: =PMT($A4/12,F$2*12,-1)*12 -> 0.12555434 | G4: =PMT($A4/12,G$2*12,-1)*12 -> 0.11449324 | H4: =PMT($A4/12,H$2*12,-1)*12 -> 0.1054546 | I4: =PMT($A4/12,I$2*12,-1)*12 -> 0.097932803 | ... AK4: =PMT($A4/12,AK$2*12,-1)*12 -> 0.041247335
A5: 0.03 | B5: =PMT($A5/12,B$2*12,-1)*12 -> 0.21562429 | C5: =PMT($A5/12,C$2*12,-1)*12 -> 0.18232411 | D5: =PMT($A5/12,D$2*12,-1)*12 -> 0.1585596 | E5: =PMT($A5/12,E$2*12,-1)*12 -> 0.14075486 | F5: =PMT($A5/12,F$2*12,-1)*12 -> 0.12692328 | G5: =PMT($A5/12,G$2*12,-1)*12 -> 0.11587289 | H5: =PMT($A5/12,H$2*12,-1)*12 -> 0.10684516 | I5: =PMT($A5/12,I$2*12,-1)*12 -> 0.099334403 | ... AK5: =PMT($A5/12,AK$2*12,-1)*12 -> 0.042958131
A6: 0.0325 | B6: =PMT($A6/12,B$2*12,-1)*12 -> 0.21696003 | C6: =PMT($A6/12,C$2*12,-1)*12 -> 0.18366934 | D6: =PMT($A6/12,D$2*12,-1)*12 -> 0.15991529 | E6: =PMT($A6/12,E$2*12,-1)*12 -> 0.14212162 | F6: =PMT($A6/12,F$2*12,-1)*12 -> 0.1283015 | G6: =PMT($A6/12,G$2*12,-1)*12 -> 0.11726283 | H6: =PMT($A6/12,H$2*12,-1)*12 -> 0.10824701 | I6: =PMT($A6/12,I$2*12,-1)*12 -> 0.10074829 | ... AK6: =PMT($A6/12,AK$2*12,-1)*12 -> 0.044704948
A7: 0.035 | B7: =PMT($A7/12,B$2*12,-1)*12 -> 0.21830094 | C7: =PMT($A7/12,C$2*12,-1)*12 -> 0.18502076 | D7: =PMT($A7/12,D$2*12,-1)*12 -> 0.16127821 | E7: =PMT($A7/12,E$2*12,-1)*12 -> 0.14349662 | F7: =PMT($A7/12,F$2*12,-1)*12 -> 0.12968897 | G7: =PMT($A7/12,G$2*12,-1)*12 -> 0.11866304 | H7: =PMT($A7/12,H$2*12,-1)*12 -> 0.10966013 | I7: =PMT($A7/12,I$2*12,-1)*12 -> 0.10217445 | ... AK7: =PMT($A7/12,AK$2*12,-1)*12 -> 0.046486915
A8: 0.0375 | B8: =PMT($A8/12,B$2*12,-1)*12 -> 0.21964702 | C8: =PMT($A8/12,C$2*12,-1)*12 -> 0.18637839 | D8: =PMT($A8/12,D$2*12,-1)*12 -> 0.16264834 | E8: =PMT($A8/12,E$2*12,-1)*12 -> 0.14487985 | F8: =PMT($A8/12,F$2*12,-1)*12 -> 0.13108569 | G8: =PMT($A8/12,G$2*12,-1)*12 -> 0.12007349 | H8: =PMT($A8/12,H$2*12,-1)*12 -> 0.11108449 | I8: =PMT($A8/12,I$2*12,-1)*12 -> 0.10361283 | ... AK8: =PMT($A8/12,AK$2*12,-1)*12 -> 0.048303121
A9: 0.04 | B9: =PMT($A9/12,B$2*12,-1)*12 -> 0.22099826 | C9: =PMT($A9/12,C$2*12,-1)*12 -> 0.1877422 | D9: =PMT($A9/12,D$2*12,-1)*12 -> 0.16402568 | E9: =PMT($A9/12,E$2*12,-1)*12 -> 0.1462713 | F9: =PMT($A9/12,F$2*12,-1)*12 -> 0.13249163 | G9: =PMT($A9/12,G$2*12,-1)*12 -> 0.12149417 | H9: =PMT($A9/12,H$2*12,-1)*12 -> 0.11252006 | I9: =PMT($A9/12,I$2*12,-1)*12 -> 0.1050634 | ... AK9: =PMT($A9/12,AK$2*12,-1)*12 -> 0.050152616
A10: 0.0425 | B10: =PMT($A10/12,B$2*12,-1)*12 -> 0.22235467 | C10: =PMT($A10/12,C$2*12,-1)*12 -> 0.18911219 | D10: =PMT($A10/12,D$2*12,-1)*12 -> 0.16541021 | E10: =PMT($A10/12,E$2*12,-1)*12 -> 0.14767096 | F10: =PMT($A10/12,F$2*12,-1)*12 -> 0.13390677 | G10: =PMT($A10/12,G$2*12,-1)*12 -> 0.12292504 | H10: =PMT($A10/12,H$2*12,-1)*12 -> 0.11396682 | I10: =PMT($A10/12,I$2*12,-1)*12 -> 0.10652613 | ... AK10: =PMT($A10/12,AK$2*12,-1)*12 -> 0.052034424
A11: 0.045 | B11: =PMT($A11/12,B$2*12,-1)*12 -> 0.22371623 | C11: =PMT($A11/12,C$2*12,-1)*12 -> 0.19048836 | D11: =PMT($A11/12,D$2*12,-1)*12 -> 0.16680194 | E11: =PMT($A11/12,E$2*12,-1)*12 -> 0.14907881 | F11: =PMT($A11/12,F$2*12,-1)*12 -> 0.13533111 | G11: =PMT($A11/12,G$2*12,-1)*12 -> 0.12436609 | H11: =PMT($A11/12,H$2*12,-1)*12 -> 0.11542472 | I11: =PMT($A11/12,I$2*12,-1)*12 -> 0.10800098 | ... AK11: =PMT($A11/12,AK$2*12,-1)*12 -> 0.05394754
A12: 0.0475 | B12: =PMT($A12/12,B$2*12,-1)*12 -> 0.22508294 | C12: =PMT($A12/12,C$2*12,-1)*12 -> 0.19187069 | D12: =PMT($A12/12,D$2*12,-1)*12 -> 0.16820084 | E12: =PMT($A12/12,E$2*12,-1)*12 -> 0.15049484 | F12: =PMT($A12/12,F$2*12,-1)*12 -> 0.13676462 | G12: =PMT($A12/12,G$2*12,-1)*12 -> 0.12581729 | H12: =PMT($A12/12,H$2*12,-1)*12 -> 0.11689375 | I12: =PMT($A12/12,I$2*12,-1)*12 -> 0.1094879 | ... AK12: =PMT($A12/12,AK$2*12,-1)*12 -> 0.055890943
A13: 0.05 | B13: =PMT($A13/12,B$2*12,-1)*12 -> 0.2264548 | C13: =PMT($A13/12,C$2*12,-1)*12 -> 0.19325919 | D13: =PMT($A13/12,D$2*12,-1)*12 -> 0.16960691 | E13: =PMT($A13/12,E$2*12,-1)*12 -> 0.15191904 | F13: =PMT($A13/12,F$2*12,-1)*12 -> 0.13820728 | G13: =PMT($A13/12,G$2*12,-1)*12 -> 0.12727862 | H13: =PMT($A13/12,H$2*12,-1)*12 -> 0.11837386 | I13: =PMT($A13/12,I$2*12,-1)*12 -> 0.11098685 | ... AK13: =PMT($A13/12,AK$2*12,-1)*12 -> 0.057863592
A14: 0.0525 | B14: =PMT($A14/12,B$2*12,-1)*12 -> 0.22783181 | C14: =PMT($A14/12,C$2*12,-1)*12 -> 0.19465384 | D14: =PMT($A14/12,D$2*12,-1)*12 -> 0.17102014 | E14: =PMT($A14/12,E$2*12,-1)*12 -> 0.15335139 | F14: =PMT($A14/12,F$2*12,-1)*12 -> 0.13965907 | G14: =PMT($A14/12,G$2*12,-1)*12 -> 0.12875004 | H14: =PMT($A14/12,H$2*12,-1)*12 -> 0.11986502 | I14: =PMT($A14/12,I$2*12,-1)*12 -> 0.11249779 | ... AK14: =PMT($A14/12,AK$2*12,-1)*12 -> 0.05986444
... A68: 0.1875 | B68: =PMT($A68/12,B$2*12,-1)*12 -> 0.30963823 | C68: =PMT($A68/12,C$2*12,-1)*12 -> 0.27880576 | D68: =PMT($A68/12,D$2*12,-1)*12 -> 0.25751662 | E68: =PMT($A68/12,E$2*12,-1)*12 -> 0.24216456 | F68: =PMT($A68/12,F$2*12,-1)*12 -> 0.23074391 | G68: =PMT($A68/12,G$2*12,-1)*12 -> 0.2220497 | H68: =PMT($A68/12,H$2*12,-1)*12 -> 0.21531417 | I68: =PMT($A68/12,I$2*12,-1)*12 -> 0.21002495 | ... AK68: =PMT($A68/12,AK$2*12,-1)*12 -> 0.18760996

Sheet Investor
A3: Property | B3: Purchase Price
A4: Property | B4: Rental Income
A5: Expenses | B5: Operating Expenses
A6: Loan | B6: Interest Rate
A7: Loan | B7: Loan Amount
A10: DSCR | B10: NOI/ Debt Service
A11: NOI=Rent-Expenses
A12: Debt Service=PMT(rate/12,term*12,loan_amount)*12
